Workbook

Sheet Data
A1: Route ID | B1: Origin | C1: Destination | D1: Distance (km) | E1: Weekly Frequency | F1: Seats | G1: load factor | H1: Fare (Rs) | I1: Flight Hours | J1: Cruise speed(km/hr) | K1: Annual departures (52 * weekly freq) | L1: Passenger per flight | M1: ASK | N1: Revenue(Rs) | O1: Fuel cost (Rs) | P1: Maintanance cost (Rs) | Q1: Other cost (Rs) | R1: Total operating cost (Rs) | S1: EBITDA (Rs) | T1: EBITDA Margin | U1: UDAN Eligible | V1: Break Even Load Factor | W1: Total Cost @ 20% Fuel | X1: Route Viability @ 20% Fuel | Y1: Structural viability | Z1: Option 1: Fare Hike | AA1: Fare After Hike | AB1: Load Factor after Hike | AC1: Passengers after hike | AD1: New Revenue after Hike | AE1: Option 1 EBITDA | AF1: Option 1 Annual EBITDA | AG1: Option 1 EBITDA Margin | AH1: 20% Fuel EBITDA | AI1: Option 2 (Y/N) | AJ1: Option 2 EBITDA | AK1: Option 2 Annual EBITDA | AL1: UDAN FARE CAP | AM1: RCS Passengers | AN1: Normal Passenger | AO1: UDAN Revenue | AP1: UDAN Fuel cost | AQ1: UDAN Airport cost | AR1: VGF Revenue | AS1: UDAN Total cost | AT1: Option 3 EBITDA | AU1: Option 3 Annual EBITDA | AV1: Option 3 EBITDA margin | AW1: Blended Strategy | AX1: Blended EBITDA | AY1: Blended Annual EBITDA | AZ1: Improvement vs +20% Fuel
A2: R01 | B2: Kanpur | C2: Delhi | D2: 440 | E2: 14 | F2: 70 | G2: 0.78 | H2: 3200 | I2: =D2/J2 -> 0.88 | J2: 500 | K2: =52*E2 -> 728 | L2: =F2*G2 -> 54.6 | M2: =F2*D2 -> 30800 | N2: =L2*H2 -> 174720 | O2: =I2*Assumptions!B3*Assumptions!B2 -> 62138.267 | P2: =I2*Assumptions!B7 -> 8800 | Q2: =Data!P2+Assumptions!B4+Assumptions!B5+Assumptions!B6 -> 64800 | R2: =Q2+O2 -> 126938.27 | S2: =N2-R2 -> 47781.733 | T2: =(S2/N2) -> 0.27347603 | U2: Y | V2: =W2/(F2*H2) -> 0.62216929 | W2: =P2+I2*Assumptions!$B$3*Assumptions!$B$2*1.2+Assumptions!$B$4+Assumptions!$B$5+Assumptions!$B$6 -> 139365.92 | X2: =IF(G2>=V2,"Viable","At Risk") -> Viable | Y2: =IF(V2>Assumptions!$B$12,"Structurally Weak","Potentially Viable") -> Potentially Viable | Z2: =Assumptions!B$10 -> 0.08 | AA2: =H2*(1+Z2) -> 3456 | AB2: =MIN(Assumptions!B$12,G2*(1+Z2*Assumptions!B$11)) -> 0.69888 | AC2: =F2*AB2 -> 48.9216 | AD2: =AC2*(AA2) -> 169073.05 | AE2: =AD2-(P2+I2*Assumptions!$B$3*Assumptions!$B$2*1.2+Assumptions!$B$4+Assumptions!$B$5+Assumptions!$B$6) -> 29707.129 | AF2: =AE2*K2 -> 21626790 | AG2: =AE2/AD2 -> 0.17570588 | AH2: ='Scenario Analysis'!D2 -> 35354.079 | AI2: =IF(AND(AH2<0,U2="N"),"Rationalize","Keep") -> Keep | AJ2: =IF(AI2="Rationalize",0,AH2) -> 35354.079 | AK2: =AJ2*K2 -> 25737770 | AL2: =IF(U2="Y",MIN(H2,Assumptions!$B$13*I2),0) -> 2200 | AM2: =IF(U2="Y",L2*Assumptions!$B$14,0) -> 27.3 | AN2: =IF(U2="Y",L2*(1-Assumptions!$B$14),0) -> 27.3 | AO2: =IF(U2="Y",AM2*AL2+AN2*H2+L2*Assumptions!$B$9,0) -> 166530 | AP2: =IF(U2="Y",O2*1.2*(1-Assumptions!$B$15),0) -> 63381.033 | AQ2: =IF(U2="Y",Assumptions!$B$5*(1-Assumptions!$B$16),0) -> 8400 | AR2: =IF(U2="Y",AM2*Assumptions!$B$17,0) -> 40950 | AS2: =IF(U2="Y",AP2+P2+Assumptions!$B$4+AQ2+Assumptions!$B$6,0) -> 122581.03 | AT2: =IF(U2="Y",AO2+AR2-AS2,0) -> 84898.967 | AU2: =AT2*K2 -> 61806448 | AV2: =IFERROR(AT2/(AO2+AR2),0) -> 0.40919109 | AW2: =IF(U2="Y",IF(AT2>=MAX(AH2,AE2,AT2),"UDAN",IF(AE2>=AH2,"Fare Hike","Keep as-is")),IF(AJ2=0,"Rationalize",IF(AE2>=AH2,"Fare Hike","Keep as-is"))) -> UDAN | AX2: =IF(AW2="UDAN",AT2,IF(AW2="Fare Hike",AE2,IF(AW2="Rationalize",0,AH2))) -> 84898.967 | AY2: =AX2*K2 -> 61806448 | AZ2: =AX2-AH2 -> 49544.888
A3: R02 | B3: Jodhpur | C3: Delhi | D3: 590 | E3: 10 | F3: 70 | G3: 0.74 | H3: 3600 | I3: =D3/J3 -> 1.18 | J3: 500 | K3: =52*E3 -> 520 | L3: =F3*G3 -> 51.8 | M3: =F3*D3 -> 41300 | N3: =L3*H3 -> 186480 | O3: =I3*Assumptions!B3*Assumptions!B2 -> 83321.768 | P3: =I3*Assumptions!B7 -> 11800 | Q3: =Data!P3+Assumptions!B4+Assumptions!B5+Assumptions!B6 -> 67800 | R3: =Q3+O3 -> 151121.77 | S3: =N3-R3 -> 35358.232 | T3: =(S3/N3) -> 0.18960871 | U3: N | V3: =W3/(F3*H3) -> 0.66581794 | W3: =P3+I3*Assumptions!$B$3*Assumptions!$B$2*1.2+Assumptions!$B$4+Assumptions!$B$5+Assumptions!$B$6 -> 167786.12 | X3: =IF(G3>=V3,"Viable","At Risk") -> Viable | Y3: =IF(V3>Assumptions!$B$12,"Structurally Weak","Potentially Viable") -> Potentially Viable | Z3: =Assumptions!B$10 -> 0.08 | AA3: =H3*(1+Z3) -> 3888 | AB3: =MIN(Assumptions!B$12,G3*(1+Z3*Assumptions!B$11)) -> 0.66304 | AC3: =F3*AB3 -> 46.4128 | AD3: =AC3*(AA3) -> 180452.97 | AE3: =AD3-(P3+I3*Assumptions!$B$3*Assumptions!$B$2*1.2+Assumptions!$B$4+Assumptions!$B$5+Assumptions!$B$6) -> 12666.845 | AF3: =AE3*K3 -> 6586759.5 | AG3: =AE3/AD3 -> 0.070194719 | AH3: ='Scenario Analysis'!D3 -> 18693.879 | AI3: =IF(AND(AH3<0,U3="N"),"Rationalize","Keep") -> Keep | AJ3: =IF(AI3="Rationalize",0,AH3) -> 18693.879 | AK3: =AJ3*K3 -> 9720817 | AL3: =IF(U3="Y",MIN(H3,Assumptions!$B$13*I3),0) -> 0 | AM3: =IF(U3="Y",L3*Assumptions!$B$14,0) -> 0 | AN3: =IF(U3="Y",L3*(1-Assumptions!$B$14),0) -> 0 | AO3: =IF(U3="Y",AM3*AL3+AN3*H3+L3*Assumptions!$B$9,0) -> 0 | AP3: =IF(U3="Y",O3*1.2*(1-Assumptions!$B$15),0) -> 0 | AQ3: =IF(U3="Y",Assumptions!$B$5*(1-Assumptions!$B$16),0) -> 0 | AR3: =IF(U3="Y",AM3*Assumptions!$B$17,0) -> 0 | AS3: =IF(U3="Y",AP3+P3+Assumptions!$B$4+AQ3+Assumptions!$B$6,0) -> 0 | AT3: =IF(U3="Y",AO3+AR3-AS3,0) -> 0 | AU3: =AT3*K3 -> 0 | AV3: =IFERROR(AT3/(AO3+AR3),0) -> 0 | AW3: =IF(U3="Y",IF(AT3>=MAX(AH3,AE3,AT3),"UDAN",IF(AE3>=AH3,"Fare Hike","Keep as-is")),IF(AJ3=0,"Rationalize",IF(AE3>=AH3,"Fare Hike","Keep as it is"))) -> Keep as it is | AX3: =IF(AW3="UDAN",AT3,IF(AW3="Fare Hike",AE3,IF(AW3="Rationalize",0,AH3))) -> 18693.879 | AY3: =AX3*K3 -> 9720817 | AZ3: =AX3-AH3 -> 0
A4: R03 | B4: Bhopal | C4: Mumbai | D4: 585 | E4: 7 | F4: 70 | G4: 0.6 | H4: 3900 | I4: =D4/J4 -> 1.17 | J4: 500 | K4: =52*E4 -> 364 | L4: =F4*G4 -> 42 | M4: =F4*D4 -> 40950 | N4: =L4*H4 -> 163800 | O4: =I4*Assumptions!B3*Assumptions!B2 -> 82615.651 | P4: =I4*Assumptions!B7 -> 11700 | Q4: =Data!P4+Assumptions!B4+Assumptions!B5+Assumptions!B6 -> 67700 | R4: =Q4+O4 -> 150315.65 | S4: =N4-R4 -> 13484.349 | T4: =(S4/N4) -> 0.082322033 | U4: N | V4: =W4/(F4*H4) -> 0.61113107 | W4: =P4+I4*Assumptions!$B$3*Assumptions!$B$2*1.2+Assumptions!$B$4+Assumptions!$B$5+Assumptions!$B$6 -> 166838.78 | X4: =IF(G4>=V4,"Viable","At Risk") -> At Risk | Y4: =IF(V4>Assumptions!$B$12,"Structurally Weak","Potentially Viable") -> Potentially Viable | Z4: =Assumptions!B$10 -> 0.08 | AA4: =H4*(1+Z4) -> 4212 | AB4: =MIN(Assumptions!B$12,G4*(1+Z4*Assumptions!B$11)) -> 0.5376 | AC4: =F4*AB4 -> 37.632 | AD4: =AC4*(AA4) -> 158505.98 | AE4: =AD4-(P4+I4*Assumptions!$B$3*Assumptions!$B$2*1.2+Assumptions!$B$4+Assumptions!$B$5+Assumptions!$B$6) -> -8332.7972 | AF4: =AE4*K4 -> -3033138.2 | AG4: =AE4/AD4 -> -0.052570868 | AH4: ='Scenario Analysis'!D4 -> -3038.7812 | AI4: =IF(AND(AH4<0,U4="N"),"Rationalize","Keep") -> Rationalize | AJ4: =IF(AI4="Rationalize",0,AH4) -> 0 | AK4: =AJ4*K4 -> 0 | AL4: =IF(U4="Y",MIN(H4,Assumptions!$B$13*I4),0) -> 0 | AM4: =IF(U4="Y",L4*Assumptions!$B$14,0) -> 0 | AN4: =IF(U4="Y",L4*(1-Assumptions!$B$14),0) -> 0 | AO4: =IF(U4="Y",AM4*AL4+AN4*H4+L4*Assumptions!$B$9,0) -> 0 | AP4: =IF(U4="Y",O4*1.2*(1-Assumptions!$B$15),0) -> 0 | AQ4: =IF(U4="Y",Assumptions!$B$5*(1-Assumptions!$B$16),0) -> 0 | AR4: =IF(U4="Y",AM4*Assumptions!$B$17,0) -> 0 | AS4: =IF(U4="Y",AP4+P4+Assumptions!$B$4+AQ4+Assumptions!$B$6,0) -> 0 | AT4: =IF(U4="Y",AO4+AR4-AS4,0) -> 0 | AU4: =AT4*K4 -> 0 | AV4: =IFERROR(AT4/(AO4+AR4),0) -> 0 | AW4: =IF(U4="Y",IF(AT4>=MAX(AH4,AE4,AT4),"UDAN",IF(AE4>=AH4,"Fare Hike","Keep as-is")),IF(AJ4=0,"Rationalize",IF(AE4>=AH4,"Fare Hike","Keep as it is"))) -> Rationalize | AX4: =IF(AW4="UDAN",AT4,IF(AW4="Fare Hike",AE4,IF(AW4="Rationalize",0,AH4))) -> 0 | AY4: =AX4*K4 -> 0 | AZ4: =AX4-AH4 -> 3038.7812
A5: R04 | B5: Coimbatore | C5: Chennai | D5: 375 | E5: 12 | F5: 70 | G5: 0.76 | H5: 2800 | I5: =D5/J5 -> 0.75 | J5: 500 | K5: =52*E5 -> 624 | L5: =F5*G5 -> 53.2 | M5: =F5*D5 -> 26250 | N5: =L5*H5 -> 148960 | O5: =I5*Assumptions!B3*Assumptions!B2 -> 52958.751 | P5: =I5*Assumptions!B7 -> 7500 | Q5: =Data!P5+Assumptions!B4+Assumptions!B5+Assumptions!B6 -> 63500 | R5: =Q5+O5 -> 116458.75 | S5: =N5-R5 -> 32501.249 | T5: =(S5/N5) -> 0.21818776 | U5: N | V5: =W5/(F5*H5) -> 0.64821684 | W5: =P5+I5*Assumptions!$B$3*Assumptions!$B$2*1.2+Assumptions!$B$4+Assumptions!$B$5+Assumptions!$B$6 -> 127050.5 | X5: =IF(G5>=V5,"Viable","At Risk") -> Viable | Y5: =IF(V5>Assumptions!$B$12,"Structurally Weak","Potentially Viable") -> Potentially Viable | Z5: =Assumptions!B$10 -> 0.08 | AA5: =H5*(1+Z5) -> 3024 | AB5: =MIN(Assumptions!B$12,G5*(1+Z5*Assumptions!B$11)) -> 0.68096 | AC5: =F5*AB5 -> 47.6672 | AD5: =AC5*(AA5) -> 144145.61 | AE5: =AD5-(P5+I5*Assumptions!$B$3*Assumptions!$B$2*1.2+Assumptions!$B$4+Assumptions!$B$5+Assumptions!$B$6) -> 17095.112 | AF5: =AE5*K5 -> 10667350 | AG5: =AE5/AD5 -> 0.11859613 | AH5: ='Scenario Analysis'!D5 -> 21909.499 | AI5: =IF(AND(AH5<0,U5="N"),"Rationalize","Keep") -> Keep | AJ5: =IF(AI5="Rationalize",0,AH5) -> 21909.499 | AK5: =AJ5*K5 -> 13671528 | AL5: =IF(U5="Y",MIN(H5,Assumptions!$B$13*I5),0) -> 0 | AM5: =IF(U5="Y",L5*Assumptions!$B$14,0) -> 0 | AN5: =IF(U5="Y",L5*(1-Assumptions!$B$14),0) -> 0 | AO5: =IF(U5="Y",AM5*AL5+AN5*H5+L5*Assumptions!$B$9,0) -> 0 | AP5: =IF(U5="Y",O5*1.2*(1-Assumptions!$B$15),0) -> 0 | AQ5: =IF(U5="Y",Assumptions!$B$5*(1-Assumptions!$B$16),0) -> 0 | AR5: =IF(U5="Y",AM5*Assumptions!$B$17,0) -> 0 | AS5: =IF(U5="Y",AP5+P5+Assumptions!$B$4+AQ5+Assumptions!$B$6,0) -> 0 | AT5: =IF(U5="Y",AO5+AR5-AS5,0) -> 0 | AU5: =AT5*K5 -> 0 | AV5: =IFERROR(AT5/(AO5+AR5),0) -> 0 | AW5: =IF(U5="Y",IF(AT5>=MAX(AH5,AE5,AT5),"UDAN",IF(AE5>=AH5,"Fare Hike","Keep as-is")),IF(AJ5=0,"Rationalize",IF(AE5>=AH5,"Fare Hike","Keep as it is"))) -> Keep as it is | AX5: =IF(AW5="UDAN",AT5,IF(AW5="Fare Hike",AE5,IF(AW5="Rationalize",0,AH5))) -> 21909.499 | AY5: =AX5*K5 -> 13671528 | AZ5: =AX5-AH5 -> 0
A6: R05 | B6: Rajkot | C6: Mumbai | D6: 400 | E6: 10 | F6: 70 | G6: 0.71 | H6: 3100 | I6: =D6/J6 -> 0.8 | J6: 500 | K6: =52*E6 -> 520 | L6: =F6*G6 -> 49.7 | M6: =F6*D6 -> 28000 | N6: =L6*H6 -> 154070 | O6: =I6*Assumptions!B3*Assumptions!B2 -> 56489.334 | P6: =I6*Assumptions!B7 -> 8000 | Q6: =Data!P6+Assumptions!B4+Assumptions!B5+Assumptions!B6 -> 64000 | R6: =Q6+O6 -> 120489.33 | S6: =N6-R6 -> 33580.666 | T6: =(S6/N6) -> 0.2179572 | U6: Y | V6: =W6/(F6*H6) -> 0.60731429 | W6: =P6+I6*Assumptions!$B$3*Assumptions!$B$2*1.2+Assumptions!$B$4+Assumptions!$B$5+Assumptions!$B$6 -> 131787.2 | X6: =IF(G6>=V6,"Viable","At Risk") -> Viable | Y6: =IF(V6>Assumptions!$B$12,"Structurally Weak","Potentially Viable") -> Potentially Viable | Z6: =Assumptions!B$10 -> 0.08 | AA6: =H6*(1+Z6) -> 3348 | AB6: =MIN(Assumptions!B$12,G6*(1+Z6*Assumptions!B$11)) -> 0.63616 | AC6: =F6*AB6 -> 44.5312 | AD6: =AC6*(AA6) -> 149090.46 | AE6: =AD6-(P6+I6*Assumptions!$B$3*Assumptions!$B$2*1.2+Assumptions!$B$4+Assumptions!$B$5+Assumptions!$B$6) -> 17303.257 | AF6: =AE6*K6 -> 8997693.5 | AG6: =AE6/AD6 -> 0.11605878 | AH6: ='Scenario Analysis'!D6 -> 22282.799 | AI6: =IF(AND(AH6<0,U6="N"),"Rationalize","Keep") -> Keep | AJ6: =IF(AI6="Rationalize",0,AH6) -> 22282.799 | AK6: =AJ6*K6 -> 11587056 | AL6: =IF(U6="Y",MIN(H6,Assumptions!$B$13*I6),0) -> 2000 | AM6: =IF(U6="Y",L6*Assumptions!$B$14,0) -> 24.85 | AN6: =IF(U6="Y",L6*(1-Assumptions!$B$14),0) -> 24.85 | AO6: =IF(U6="Y",AM6*AL6+AN6*H6+L6*Assumptions!$B$9,0) -> 144130 | AP6: =IF(U6="Y",O6*1.2*(1-Assumptions!$B$15),0) -> 57619.121 | AQ6: =IF(U6="Y",Assumptions!$B$5*(1-Assumptions!$B$16),0) -> 8400 | AR6: =IF(U6="Y",AM6*Assumptions!$B$17,0) -> 37275 | AS6: =IF(U6="Y",AP6+P6+Assumptions!$B$4+AQ6+Assumptions!$B$6,0) -> 116019.12 | AT6: =IF(U6="Y",AO6+AR6-AS6,0) -> 65385.879 | AU6: =AT6*K6 -> 34000657 | AV6: =IFERROR(AT6/(AO6+AR6),0) -> 0.36044144 | AW6: =IF(U6="Y",IF(AT6>=MAX(AH6,AE6,AT6),"UDAN",IF(AE6>=AH6,"Fare Hike","Keep as-is")),IF(AJ6=0,"Rationalize",IF(AE6>=AH6,"Fare Hike","Keep as it is"))) -> UDAN | AX6: =IF(AW6="UDAN",AT6,IF(AW6="Fare Hike",AE6,IF(AW6="Rationalize",0,AH6))) -> 65385.879 | AY6: =AX6*K6 -> 34000657 | AZ6: =AX6-AH6 -> 43103.08
A7: R06 | B7: Varanasi | C7: Delhi | D7: 660 | E7: 9 | F7: 70 | G7: 0.69 | H7: 3800 | I7: =D7/J7 -> 1.32 | J7: 500 | K7: =52*E7 -> 468 | L7: =F7*G7 -> 48.3 | M7: =F7*D7 -> 46200 | N7: =L7*H7 -> 183540 | O7: =I7*Assumptions!B3*Assumptions!B2 -> 93207.401 | P7: =I7*Assumptions!B7 -> 13200 | Q7: =Data!P7+Assumptions!B4+Assumptions!B5+Assumptions!B6 -> 69200 | R7: =Q7+O7 -> 162407.4 | S7: =N7-R7 -> 21132.599 | T7: =(S7/N7) -> 0.11513893 | U7: N | V7: =W7/(F7*H7) -> 0.68063489 | W7: =P7+I7*Assumptions!$B$3*Assumptions!$B$2*1.2+Assumptions!$B$4+Assumptions!$B$5+Assumptions!$B$6 -> 181048.88 | X7: =IF(G7>=V7,"Viable","At Risk") -> Viable | Y7: =IF(V7>Assumptions!$B$12,"Structurally Weak","Potentially Viable") -> Potentially Viable | Z7: =Assumptions!B$10 -> 0.08 | AA7: =H7*(1+Z7) -> 4104 | AB7: =MIN(Assumptions!B$12,G7*(1+Z7*Assumptions!B$11)) -> 0.61824 | AC7: =F7*AB7 -> 43.2768 | AD7: =AC7*(AA7) -> 177607.99 | AE7: =AD7-(P7+I7*Assumptions!$B$3*Assumptions!$B$2*1.2+Assumptions!$B$4+Assumptions!$B$5+Assumptions!$B$6) -> -3440.8941 | AF7: =AE7*K7 -> -1610338.4 | AG7: =AE7/AD7 -> -0.019373533 | AH7: ='Scenario Analysis'!D7 -> 2491.1187 | AI7: =IF(AND(AH7<0,U7="N"),"Rationalize","Keep") -> Keep | AJ7: =IF(AI7="Rationalize",0,AH7) -> 2491.1187 | AK7: =AJ7*K7 -> 1165843.5 | AL7: =IF(U7="Y",MIN(H7,Assumptions!$B$13*I7),0) -> 0 | AM7: =IF(U7="Y",L7*Assumptions!$B$14,0) -> 0 | AN7: =IF(U7="Y",L7*(1-Assumptions!$B$14),0) -> 0 | AO7: =IF(U7="Y",AM7*AL7+AN7*H7+L7*Assumptions!$B$9,0) -> 0 | AP7: =IF(U7="Y",O7*1.2*(1-Assumptions!$B$15),0) -> 0 | AQ7: =IF(U7="Y",Assumptions!$B$5*(1-Assumptions!$B$16),0) -> 0 | AR7: =IF(U7="Y",AM7*Assumptions!$B$17,0) -> 0 | AS7: =IF(U7="Y",AP7+P7+Assumptions!$B$4+AQ7+Assumptions!$B$6,0) -> 0 | AT7: =IF(U7="Y",AO7+AR7-AS7,0) -> 0 | AU7: =AT7*K7 -> 0 | AV7: =IFERROR(AT7/(AO7+AR7),0) -> 0 | AW7: =IF(U7="Y",IF(AT7>=MAX(AH7,AE7,AT7),"UDAN",IF(AE7>=AH7,"Fare Hike","Keep as-is")),IF(AJ7=0,"Rationalize",IF(AE7>=AH7,"Fare Hike","Keep as it is"))) -> Keep as it is | AX7: =IF(AW7="UDAN",AT7,IF(AW7="Fare Hike",AE7,IF(AW7="Rationalize",0,AH7))) -> 2491.1187 | AY7: =AX7*K7 -> 1165843.5 | AZ7: =AX7-AH7 -> 0
A8: R07 | B8: Jabalpur | C8: Delhi | D8: 700 | E8: 5 | F8: 70 | G8: 0.62 | H8: 4200 | I8: =D8/J8 -> 1.4 | J8: 500 | K8: =52*E8 -> 260 | L8: =F8*G8 -> 43.4 | M8: =F8*D8 -> 49000 | N8: =L8*H8 -> 182280 | O8: =I8*Assumptions!B3*Assumptions!B2 -> 98856.334 | P8: =I8*Assumptions!B7 -> 14000 | Q8: =Data!P8+Assumptions!B4+Assumptions!B5+Assumptions!B6 -> 70000 | R8: =Q8+O8 -> 168856.33 | S8: =N8-R8 -> 13423.666 | T8: =(S8/N8) -> 0.073643107 | U8: Y | V8: =W8/(F8*H8) -> 0.64159048 | W8: =P8+I8*Assumptions!$B$3*Assumptions!$B$2*1.2+Assumptions!$B$4+Assumptions!$B$5+Assumptions!$B$6 -> 188627.6 | X8: =IF(G8>=V8,"Viable","At Risk") -> At Risk | Y8: =IF(V8>Assumptions!$B$12,"Structurally Weak","Potentially Viable") -> Potentially Viable | Z8: =Assumptions!B$10 -> 0.08 | AA8: =H8*(1+Z8) -> 4536 | AB8: =MIN(Assumptions!B$12,G8*(1+Z8*Assumptions!B$11)) -> 0.55552 | AC8: =F8*AB8 -> 38.8864 | AD8: =AC8*(AA8) -> 176388.71 | AE8: =AD8-(P8+I8*Assumptions!$B$3*Assumptions!$B$2*1.2+Assumptions!$B$4+Assumptions!$B$5+Assumptions!$B$6) -> -12238.891 | AF8: =AE8*K8 -> -3182111.7 | AG8: =AE8/AD8 -> -0.069385909 | AH8: ='Scenario Analysis'!D8 -> -6347.6014 | AI8: =IF(AND(AH8<0,U8="N"),"Rationalize","Keep") -> Keep | AJ8: =IF(AI8="Rationalize",0,AH8) -> -6347.6014 | AK8: =AJ8*K8 -> -1650376.4 | AL8: =IF(U8="Y",MIN(H8,Assumptions!$B$13*I8),0) -> 3500 | AM8: =IF(U8="Y",L8*Assumptions!$B$14,0) -> 21.7 | AN8: =IF(U8="Y",L8*(1-Assumptions!$B$14),0) -> 21.7 | AO8: =IF(U8="Y",AM8*AL8+AN8*H8+L8*Assumptions!$B$9,0) -> 182280 | AP8: =IF(U8="Y",O8*1.2*(1-Assumptions!$B$15),0) -> 100833.46 | AQ8: =IF(U8="Y",Assumptions!$B$5*(1-Assumptions!$B$16),0) -> 8400 | AR8: =IF(U8="Y",AM8*Assumptions!$B$17,0) -> 32550 | AS8: =IF(U8="Y",AP8+P8+Assumptions!$B$4+AQ8+Assumptions!$B$6,0) -> 165233.46 | AT8: =IF(U8="Y",AO8+AR8-AS8,0) -> 49596.539 | AU8: =AT8*K8 -> 12895100 | AV8: =IFERROR(AT8/(AO8+AR8),0) -> 0.23086412 | AW8: =IF(U8="Y",IF(AT8>=MAX(AH8,AE8,AT8),"UDAN",IF(AE8>=AH8,"Fare Hike","Keep as-is")),IF(AJ8=0,"Rationalize",IF(AE8>=AH8,"Fare Hike","Keep as it is"))) -> UDAN | AX8: =IF(AW8="UDAN",AT8,IF(AW8="Fare Hike",AE8,IF(AW8="Rationalize",0,AH8))) -> 49596.539 | AY8: =AX8*K8 -> 12895100 | AZ8: =AX8-AH8 -> 55944.14
A9: R08 | B9: Aurangabad | C9: Mumbai | D9: 330 | E9: 11 | F9: 70 | G9: 0.73 | H9: 2600 | I9: =D9/J9 -> 0.66 | J9: 500 | K9: =52*E9 -> 572 | L9: =F9*G9 -> 51.1 | M9: =F9*D9 -> 23100 | N9: =L9*H9 -> 132860 | O9: =I9*Assumptions!B3*Assumptions!B2 -> 46603.701 | P9: =I9*Assumptions!B7 -> 6600 | Q9: =Data!P9+Assumptions!B4+Assumptions!B5+Assumptions!B6 -> 62600 | R9: =Q9+O9 -> 109203.7 | S9: =N9-R9 -> 23656.299 | T9: =(S9/N9) -> 0.17805434 | U9: N | V9: =W9/(F9*H9) -> 0.65123319 | W9: =P9+I9*Assumptions!$B$3*Assumptions!$B$2*1.2+Assumptions!$B$4+Assumptions!$B$5+Assumptions!$B$6 -> 118524.44 | X9: =IF(G9>=V9,"Viable","At Risk") -> Viable | Y9: =IF(V9>Assumptions!$B$12,"Structurally Weak","Potentially Viable") -> Potentially Viable | Z9: =Assumptions!B$10 -> 0.08 | AA9: =H9*(1+Z9) -> 2808 | AB9: =MIN(Assumptions!B$12,G9*(1+Z9*Assumptions!B$11)) -> 0.65408 | AC9: =F9*AB9 -> 45.7856 | AD9: =AC9*(AA9) -> 128565.96 | AE9: =AD9-(P9+I9*Assumptions!$B$3*Assumptions!$B$2*1.2+Assumptions!$B$4+Assumptions!$B$5+Assumptions!$B$6) -> 10041.524 | AF9: =AE9*K9 -> 5743751.8 | AG9: =AE9/AD9 -> 0.078104062 | AH9: ='Scenario Analysis'!D9 -> 14335.559 | AI9: =IF(AND(AH9<0,U9="N"),"Rationalize","Keep") -> Keep | AJ9: =IF(AI9="Rationalize",0,AH9) -> 14335.559 | AK9: =AJ9*K9 -> 8199939.9 | AL9: =IF(U9="Y",MIN(H9,Assumptions!$B$13*I9),0) -> 0 | AM9: =IF(U9="Y",L9*Assumptions!$B$14,0) -> 0 | AN9: =IF(U9="Y",L9*(1-Assumptions!$B$14),0) -> 0 | AO9: =IF(U9="Y",AM9*AL9+AN9*H9+L9*Assumptions!$B$9,0) -> 0 | AP9: =IF(U9="Y",O9*1.2*(1-Assumptions!$B$15),0) -> 0 | AQ9: =IF(U9="Y",Assumptions!$B$5*(1-Assumptions!$B$16),0) -> 0 | AR9: =IF(U9="Y",AM9*Assumptions!$B$17,0) -> 0 | AS9: =IF(U9="Y",AP9+P9+Assumptions!$B$4+AQ9+Assumptions!$B$6,0) -> 0 | AT9: =IF(U9="Y",AO9+AR9-AS9,0) -> 0 | AU9: =AT9*K9 -> 0 | AV9: =IFERROR(AT9/(AO9+AR9),0) -> 0 | AW9: =IF(U9="Y",IF(AT9>=MAX(AH9,AE9,AT9),"UDAN",IF(AE9>=AH9,"Fare Hike","Keep as-is")),IF(AJ9=0,"Rationalize",IF(AE9>=AH9,"Fare Hike","Keep as it is"))) -> Keep as it is | AX9: =IF(AW9="UDAN",AT9,IF(AW9="Fare Hike",AE9,IF(AW9="Rationalize",0,AH9))) -> 14335.559 | AY9: =AX9*K9 -> 8199939.9 | AZ9: =AX9-AH9 -> 0
A10: R09 | B10: Belgavi | C10: Bengaluru | D10: 320 | E10: 7 | F10: 70 | G10: 0.67 | H10: 2500 | I10: =D10/J10 -> 0.64 | J10: 500 | K10: =52*E10 -> 364 | L10: =F10*G10 -> 46.9 | M10: =F10*D10 -> 22400 | N10: =L10*H10 -> 117250 | O10: =I10*Assumptions!B3*Assumptions!B2 -> 45191.467 | P10: =I10*Assumptions!B7 -> 6400 | Q10: =Data!P10+Assumptions!B4+Assumptions!B5+Assumptions!B6 -> 62400 | R10: =Q10+O10 -> 107591.47 | S10: =N10-R10 -> 9658.5328 | T10: =(S10/N10) -> 0.082375546 | U10: Y | V10: =W10/(F10*H10) -> 0.66645578 | W10: =P10+I10*Assumptions!$B$3*Assumptions!$B$2*1.2+Assumptions!$B$4+Assumptions!$B$5+Assumptions!$B$6 -> 116629.76 | X10: =IF(G10>=V10,"Viable","At Risk") -> Viable | Y10: =IF(V10>Assumptions!$B$12,"Structurally Weak","Potentially Viable") -> Potentially Viable | Z10: =Assumptions!B$10 -> 0.08 | AA10: =H10*(1+Z10) -> 2700 | AB10: =MIN(Assumptions!B$12,G10*(1+Z10*Assumptions!B$11)) -> 0.60032 | AC10: =F10*AB10 -> 42.0224 | AD10: =AC10*(AA10) -> 113460.48 | AE10: =AD10-(P10+I10*Assumptions!$B$3*Assumptions!$B$2*1.2+Assumptions!$B$4+Assumptions!$B$5+Assumptions!$B$6) -> -3169.2806 | AF10: =AE10*K10 -> -1153618.2 | AG10: =AE10/AD10 -> -0.027932904 | AH10: ='Scenario Analysis'!D10 -> 620.23936 | AI10: =IF(AND(AH10<0,U10="N"),"Rationalize","Keep") -> Keep | AJ10: =IF(AI10="Rationalize",0,AH10) -> 620.23936 | AK10: =AJ10*K10 -> 225767.13 | AL10: =IF(U10="Y",MIN(H10,Assumptions!$B$13*I10),0) -> 1600 | AM10: =IF(U10="Y",L10*Assumptions!$B$14,0) -> 23.45 | AN10: =IF(U10="Y",L10*(1-Assumptions!$B$14),0) -> 23.45 | AO10: =IF(U10="Y",AM10*AL10+AN10*H10+L10*Assumptions!$B$9,0) -> 112560 | AP10: =IF(U10="Y",O10*1.2*(1-Assumptions!$B$15),0) -> 46095.297 | AQ10: =IF(U10="Y",Assumptions!$B$5*(1-Assumptions!$B$16),0) -> 8400 | AR10: =IF(U10="Y",AM10*Assumptions!$B$17,0) -> 35175 | AS10: =IF(U10="Y",AP10+P10+Assumptions!$B$4+AQ10+Assumptions!$B$6,0) -> 102895.3 | AT10: =IF(U10="Y",AO10+AR10-AS10,0) -> 44839.703 | AU10: =AT10*K10 -> 16321652 | AV10: =IFERROR(AT10/(AO10+AR10),0) -> 0.30351442 | AW10: =IF(U10="Y",IF(AT10>=MAX(AH10,AE10,AT10),"UDAN",IF(AE10>=AH10,"Fare Hike","Keep as-is")),IF(AJ10=0,"Rationalize",IF(AE10>=AH10,"Fare Hike","Keep as it is"))) -> UDAN | AX10: =IF(AW10="UDAN",AT10,IF(AW10="Fare Hike",AE10,IF(AW10="Rationalize",0,AH10))) -> 44839.703 | AY10: =AX10*K10 -> 16321652 | AZ10: =AX10-AH10 -> 44219.464
A11: R10 | B11: Tirupati | C11: Hyderabad | D11: 460 | E11: 8 | F11: 70 | G11: 0.7 | H11: 3000 | I11: =D11/J11 -> 0.92 | J11: 500 | K11: =52*E11 -> 416 | L11: =F11*G11 -> 49 | M11: =F11*D11 -> 32200 | N11: =L11*H11 -> 147000 | O11: =I11*Assumptions!B3*Assumptions!B2 -> 64962.734 | P11: =I11*Assumptions!B7 -> 9200 | Q11: =Data!P11+Assumptions!B4+Assumptions!B5+Assumptions!B6 -> 65200 | R11: =Q11+O11 -> 130162.73 | S11: =N11-R11 -> 16837.266 | T11: =(S11/N11) -> 0.11453922 | U11: N | V11: =W11/(F11*H11) -> 0.68169181 | W11: =P11+I11*Assumptions!$B$3*Assumptions!$B$2*1.2+Assumptions!$B$4+Assumptions!$B$5+Assumptions!$B$6 -> 143155.28 | X11: =IF(G11>=V11,"Viable","At Risk") -> Viable | Y11: =IF(V11>Assumptions!$B$12,"Structurally Weak","Potentially Viable") -> Potentially Viable | Z11: =Assumptions!B$10 -> 0.08 | AA11: =H11*(1+Z11) -> 3240 | AB11: =MIN(Assumptions!B$12,G11*(1+Z11*Assumptions!B$11)) -> 0.6272 | AC11: =F11*AB11 -> 43.904 | AD11: =AC11*(AA11) -> 142248.96 | AE11: =AD11-(P11+I11*Assumptions!$B$3*Assumptions!$B$2*1.2+Assumptions!$B$4+Assumptions!$B$5+Assumptions!$B$6) -> -906.32092 | AF11: =AE11*K11 -> -377029.5 | AG11: =AE11/AD11 -> -0.0063713712 | AH11: ='Scenario Analysis'!D11 -> 3844.7191 | AI11: =IF(AND(AH11<0,U11="N"),"Rationalize","Keep") -> Keep | AJ11: =IF(AI11="Rationalize",0,AH11) -> 3844.7191 | AK11: =AJ11*K11 -> 1599403.1 | AL11: =IF(U11="Y",MIN(H11,Assumptions!$B$13*I11),0) -> 0 | AM11: =IF(U11="Y",L11*Assumptions!$B$14,0) -> 0 | AN11: =IF(U11="Y",L11*(1-Assumptions!$B$14),0) -> 0 | AO11: =IF(U11="Y",AM11*AL11+AN11*H11+L11*Assumptions!$B$9,0) -> 0 | AP11: =IF(U11="Y",O11*1.2*(1-Assumptions!$B$15),0) -> 0 | AQ11: =IF(U11="Y",Assumptions!$B$5*(1-Assumptions!$B$16),0) -> 0 | AR11: =IF(U11="Y",AM11*Assumptions!$B$17,0) -> 0 | AS11: =IF(U11="Y",AP11+P11+Assumptions!$B$4+AQ11+Assumptions!$B$6,0) -> 0 | AT11: =IF(U11="Y",AO11+AR11-AS11,0) -> 0 | AU11: =AT11*K11 -> 0 | AV11: =IFERROR(AT11/(AO11+AR11),0) -> 0 | AW11: =IF(U11="Y",IF(AT11>=MAX(AH11,AE11,AT11),"UDAN",IF(AE11>=AH11,"Fare Hike","Keep as-is")),IF(AJ11=0,"Rationalize",IF(AE11>=AH11,"Fare Hike","Keep as it is"))) -> Keep as it is | AX11: =IF(AW11="UDAN",AT11,IF(AW11="Fare Hike",AE11,IF(AW11="Rationalize",0,AH11))) -> 3844.7191 | AY11: =AX11*K11 -> 1599403.1 | AZ11: =AX11-AH11 -> 0
A12: R11 | B12: Bikaner | C12: Delhi | D12: 480 | E12: 4 | F12: 70 | G12: 0.65 | H12: 3500 | I12: =D12/J12 -> 0.96 | J12: 500 | K12: =52*E12 -> 208 | L12: =F12*G12 -> 45.5 | M12: =F12*D12 -> 33600 | N12: =L12*H12 -> 159250 | O12: =I12*Assumptions!B3*Assumptions!B2 -> 67787.201 | P12: =I12*Assumptions!B7 -> 9600 | Q12: =Data!P12+Assumptions!B4+Assumptions!B5+Assumptions!B6 -> 65600 | R12: =Q12+O12 -> 133387.2 | S12: =N12-R12 -> 25862.799 | T12: =(S12/N12) -> 0.16240376 | U12: Y | V12: =W12/(F12*H12) -> 0.59977404 | W12: =P12+I12*Assumptions!$B$3*Assumptions!$B$2*1.2+Assumptions!$B$4+Assumptions!$B$5+Assumptions!$B$6 -> 146944.64 | X12: =IF(G12>=V12,"Viable","At Risk") -> Viable | Y12: =IF(V12>Assumptions!$B$12,"Structurally Weak","Potentially Viable") -> Potentially Viable | Z12: =Assumptions!B$10 -> 0.08 | AA12: =H12*(1+Z12) -> 3780 | AB12: =MIN(Assumptions!B$12,G12*(1+Z12*Assumptions!B$11)) -> 0.5824 | AC12: =F12*AB12 -> 40.768 | AD12: =AC12*(AA12) -> 154103.04 | AE12: =AD12-(P12+I12*Assumptions!$B$3*Assumptions!$B$2*1.2+Assumptions!$B$4+Assumptions!$B$5+Assumptions!$B$6) -> 7158.399 | AF12: =AE12*K12 -> 1488947 | AG12: =AE12/AD12 -> 0.04645203 | AH12: ='Scenario Analysis'!D12 -> 12305.359 | AI12: =IF(AND(AH12<0,U12="N"),"Rationalize","Keep") -> Keep | AJ12: =IF(AI12="Rationalize",0,AH12) -> 12305.359 | AK12: =AJ12*K12 -> 2559514.7 | AL12: =IF(U12="Y",MIN(H12,Assumptions!$B$13*I12),0) -> 2400 | AM12: =IF(U12="Y",L12*Assumptions!$B$14,0) -> 22.75 | AN12: =IF(U12="Y",L12*(1-Assumptions!$B$14),0) -> 22.75 | AO12: =IF(U12="Y",AM12*AL12+AN12*H12+L12*Assumptions!$B$9,0) -> 150150 | AP12: =IF(U12="Y",O12*1.2*(1-Assumptions!$B$15),0) -> 69142.945 | AQ12: =IF(U12="Y",Assumptions!$B$5*(1-Assumptions!$B$16),0) -> 8400 | AR12: =IF(U12="Y",AM12*Assumptions!$B$17,0) -> 34125 | AS12: =IF(U12="Y",AP12+P12+Assumptions!$B$4+AQ12+Assumptions!$B$6,0) -> 129142.94 | AT12: =IF(U12="Y",AO12+AR12-AS12,0) -> 55132.055 | AU12: =AT12*K12 -> 11467467 | AV12: =IFERROR(AT12/(AO12+AR12),0) -> 0.29918359 | AW12: =IF(U12="Y",IF(AT12>=MAX(AH12,AE12,AT12),"UDAN",IF(AE12>=AH12,"Fare Hike","Keep as-is")),IF(AJ12=0,"Rationalize",IF(AE12>=AH12,"Fare Hike","Keep as it is"))) -> UDAN | AX12: =IF(AW12="UDAN",AT12,IF(AW12="Fare Hike",AE12,IF(AW12="Rationalize",0,AH12))) -> 55132.055 | AY12: =AX12*K12 -> 11467467 | AZ12: =AX12-AH12 -> 42826.696
A13: R12 | B13: Jamnagar | C13: Mumbai | D13: 480 | E13: 6 | F13: 70 | G13: 0.68 | H13: 3300 | I13: =D13/J13 -> 0.96 | J13: 500 | K13: =52*E13 -> 312 | L13: =F13*G13 -> 47.6 | M13: =F13*D13 -> 33600 | N13: =L13*H13 -> 157080 | O13: =I13*Assumptions!B3*Assumptions!B2 -> 67787.201 | P13: =I13*Assumptions!B7 -> 9600 | Q13: =Data!P13+Assumptions!B4+Assumptions!B5+Assumptions!B6 -> 65600 | R13: =Q13+O13 -> 133387.2 | S13: =N13-R13 -> 23692.799 | T13: =(S13/N13) -> 0.15083269 | U13: Y | V13: =W13/(F13*H13) -> 0.63612399 | W13: =P13+I13*Assumptions!$B$3*Assumptions!$B$2*1.2+Assumptions!$B$4+Assumptions!$B$5+Assumptions!$B$6 -> 146944.64 | X13: =IF(G13>=V13,"Viable","At Risk") -> Viable | Y13: =IF(V13>Assumptions!$B$12,"Structurally Weak","Potentially Viable") -> Potentially Viable | Z13: =Assumptions!B$10 -> 0.08 | AA13: =H13*(1+Z13) -> 3564 | AB13: =MIN(Assumptions!B$12,G13*(1+Z13*Assumptions!B$11)) -> 0.60928 | AC13: =F13*AB13 -> 42.6496 | AD13: =AC13*(AA13) -> 152003.17 | AE13: =AD13-(P13+I13*Assumptions!$B$3*Assumptions!$B$2*1.2+Assumptions!$B$4+Assumptions!$B$5+Assumptions!$B$6) -> 5058.5334 | AF13: =AE13*K13 -> 1578262.4 | AG13: =AE13/AD13 -> 0.03327913 | AH13: ='Scenario Analysis'!D13 -> 10135.359 | AI13: =IF(AND(AH13<0,U13="N"),"Rationalize","Keep") -> Keep | AJ13: =IF(AI13="Rationalize",0,AH13) -> 10135.359 | AK13: =AJ13*K13 -> 3162232 | AL13: =IF(U13="Y",MIN(H13,Assumptions!$B$13*I13),0) -> 2400 | AM13: =IF(U13="Y",L13*Assumptions!$B$14,0) -> 23.8 | AN13: =IF(U13="Y",L13*(1-Assumptions!$B$14),0) -> 23.8 | AO13: =IF(U13="Y",AM13*AL13+AN13*H13+L13*Assumptions!$B$9,0) -> 152320 | AP13: =IF(U13="Y",O13*1.2*(1-Assumptions!$B$15),0) -> 69142.945 | AQ13: =IF(U13="Y",Assumptions!$B$5*(1-Assumptions!$B$16),0) -> 8400 | AR13: =IF(U13="Y",AM13*Assumptions!$B$17,0) -> 35700 | AS13: =IF(U13="Y",AP13+P13+Assumptions!$B$4+AQ13+Assumptions!$B$6,0) -> 129142.94 | AT13: =IF(U13="Y",AO13+AR13-AS13,0) -> 58877.055 | AU13: =AT13*K13 -> 18369641 | AV13: =IFERROR(AT13/(AO13+AR13),0) -> 0.31314251 | AW13: =IF(U13="Y",IF(AT13>=MAX(AH13,AE13,AT13),"UDAN",IF(AE13>=AH13,"Fare Hike","Keep as-is")),IF(AJ13=0,"Rationalize",IF(AE13>=AH13,"Fare Hike","Keep as it is"))) -> UDAN | AX13: =IF(AW13="UDAN",AT13,IF(AW13="Fare Hike",AE13,IF(AW13="Rationalize",0,AH13))) -> 58877.055 | AY13: =AX13*K13 -> 18369641 | AZ13: =AX13-AH13 -> 48741.696
A14: R13 | B14: Kolhapur | C14: Mumbai | D14: 380 | E14: 9 | F14: 70 | G14: 0.72 | H14: 2700 | I14: =D14/J14 -> 0.76 | J14: 500 | K14: =52*E14 -> 468 | L14: =F14*G14 -> 50.4 | M14: =F14*D14 -> 26600 | N14: =L14*H14 -> 136080 | O14: =I14*Assumptions!B3*Assumptions!B2 -> 53664.867 | P14: =I14*Assumptions!B7 -> 7600 | Q14: =Data!P14+Assumptions!B4+Assumptions!B5+Assumptions!B6 -> 63600 | R14: =Q14+O14 -> 117264.87 | S14: =N14-R14 -> 18815.133 | T14: =(S14/N14) -> 0.13826523 | U14: Y | V14: =W14/(F14*H14) -> 0.67723725 | W14: =P14+I14*Assumptions!$B$3*Assumptions!$B$2*1.2+Assumptions!$B$4+Assumptions!$B$5+Assumptions!$B$6 -> 127997.84 | X14: =IF(G14>=V14,"Viable","At Risk") -> Viable | Y14: =IF(V14>Assumptions!$B$12,"Structurally Weak","Potentially Viable") -> Potentially Viable | Z14: =Assumptions!B$10 -> 0.08 | AA14: =H14*(1+Z14) -> 2916 | AB14: =MIN(Assumptions!B$12,G14*(1+Z14*Assumptions!B$11)) -> 0.64512 | AC14: =F14*AB14 -> 45.1584 | AD14: =AC14*(AA14) -> 131681.89 | AE14: =AD14-(P14+I14*Assumptions!$B$3*Assumptions!$B$2*1.2+Assumptions!$B$4+Assumptions!$B$5+Assumptions!$B$6) -> 3684.0536 | AF14: =AE14*K14 -> 1724137.1 | AG14: =AE14/AD14 -> 0.027976919 | AH14: ='Scenario Analysis'!D14 -> 8082.1592 | AI14: =IF(AND(AH14<0,U14="N"),"Rationalize","Keep") -> Keep | AJ14: =IF(AI14="Rationalize",0,AH14) -> 8082.1592 | AK14: =AJ14*K14 -> 3782450.5 | AL14: =IF(U14="Y",MIN(H14,Assumptions!$B$13*I14),0) -> 1900 | AM14: =IF(U14="Y",L14*Assumptions!$B$14,0) -> 25.2 | AN14: =IF(U14="Y",L14*(1-Assumptions!$B$14),0) -> 25.2 | AO14: =IF(U14="Y",AM14*AL14+AN14*H14+L14*Assumptions!$B$9,0) -> 133560 | AP14: =IF(U14="Y",O14*1.2*(1-Assumptions!$B$15),0) -> 54738.165 | AQ14: =IF(U14="Y",Assumptions!$B$5*(1-Assumptions!$B$16),0) -> 8400 | AR14: =IF(U14="Y",AM14*Assumptions!$B$17,0) -> 37800 | AS14: =IF(U14="Y",AP14+P14+Assumptions!$B$4+AQ14+Assumptions!$B$6,0) -> 112738.16 | AT14: =IF(U14="Y",AO14+AR14-AS14,0) -> 58621.835 | AU14: =AT14*K14 -> 27435019 | AV14: =IFERROR(AT14/(AO14+AR14),0) -> 0.34209755 | AW14: =IF(U14="Y",IF(AT14>=MAX(AH14,AE14,AT14),"UDAN",IF(AE14>=AH14,"Fare Hike","Keep as-is")),IF(AJ14=0,"Rationalize",IF(AE14>=AH14,"Fare Hike","Keep as it is"))) -> UDAN | AX14: =IF(AW14="UDAN",AT14,IF(AW14="Fare Hike",AE14,IF(AW14="Rationalize",0,AH14))) -> 58621.835 | AY14: =AX14*K14 -> 27435019 | AZ14: =AX14-AH14 -> 50539.676
A15: R14 | B15: Gwalior | C15: Delhi | D15: 300 | E15: 10 | F15: 70 | G15: 0.75 | H15: 2400 | I15: =D15/J15 -> 0.6 | J15: 500 | K15: =52*E15 -> 520 | L15: =F15*G15 -> 52.5 | M15: =F15*D15 -> 21000 | N15: =L15*H15 -> 126000 | O15: =I15*Assumptions!B3*Assumptions!B2 -> 42367.001 | P15: =I15*Assumptions!B7 -> 6000 | Q15: =Data!P15+Assumptions!B4+Assumptions!B5+Assumptions!B6 -> 62000 | R15: =Q15+O15 -> 104367 | S15: =N15-R15 -> 21633 | T15: =(S15/N15) -> 0.17169047 | U15: Y | V15: =W15/(F15*H15) -> 0.67166905 | W15: =P15+I15*Assumptions!$B$3*Assumptions!$B$2*1.2+Assumptions!$B$4+Assumptions!$B$5+Assumptions!$B$6 -> 112840.4 | X15: =IF(G15>=V15,"Viable","At Risk") -> Viable | Y15: =IF(V15>Assumptions!$B$12,"Structurally Weak","Potentially Viable") -> Potentially Viable | Z15: =Assumptions!B$10 -> 0.08 | AA15: =H15*(1+Z15) -> 2592 | AB15: =MIN(Assumptions!B$12,G15*(1+Z15*Assumptions!B$11)) -> 0.672 | AC15: =F15*AB15 -> 47.04 | AD15: =AC15*(AA15) -> 121927.68 | AE15: =AD15-(P15+I15*Assumptions!$B$3*Assumptions!$B$2*1.2+Assumptions!$B$4+Assumptions!$B$5+Assumptions!$B$6) -> 9087.2794 | AF15: =AE15*K15 -> 4725385.3 | AG15: =AE15/AD15 -> 0.074530077 | AH15: ='Scenario Analysis'!D15 -> 13159.599 | AI15: =IF(AND(AH15<0,U15="N"),"Rationalize","Keep") -> Keep | AJ15: =IF(AI15="Rationalize",0,AH15) -> 13159.599 | AK15: =AJ15*K15 -> 6842991.7 | AL15: =IF(U15="Y",MIN(H15,Assumptions!$B$13*I15),0) -> 1500 | AM15: =IF(U15="Y",L15*Assumptions!$B$14,0) -> 26.25 | AN15: =IF(U15="Y",L15*(1-Assumptions!$B$14),0) -> 26.25 | AO15: =IF(U15="Y",AM15*AL15+AN15*H15+L15*Assumptions!$B$9,0) -> 120750 | AP15: =IF(U15="Y",O15*1.2*(1-Assumptions!$B$15),0) -> 43214.341 | AQ15: =IF(U15="Y",Assumptions!$B$5*(1-Assumptions!$B$16),0) -> 8400 | AR15: =IF(U15="Y",AM15*Assumptions!$B$17,0) -> 39375 | AS15: =IF(U15="Y",AP15+P15+Assumptions!$B$4+AQ15+Assumptions!$B$6,0) -> 99614.341 | AT15: =IF(U15="Y",AO15+AR15-AS15,0) -> 60510.659 | AU15: =AT15*K15 -> 31465543 | AV15: =IFERROR(AT15/(AO15+AR15),0) -> 0.37789639 | AW15: =IF(U15="Y",IF(AT15>=MAX(AH15,AE15,AT15),"UDAN",IF(AE15>=AH15,"Fare Hike","Keep as-is")),IF(AJ15=0,"Rationalize",IF(AE15>=AH15,"Fare Hike","Keep as it is"))) -> UDAN | AX15: =IF(AW15="UDAN",AT15,IF(AW15="Fare Hike",AE15,IF(AW15="Rationalize",0,AH15))) -> 60510.659 | AY15: =AX15*K15 -> 31465543 | AZ15: =AX15-AH15 -> 47351.06
A16: R15 | B16: Hubali | C16: Bengaluru | D16: 400 | E16: 7 | F16: 70 | G16: 0.66 | H16: 2800 | I16: =D16/J16 -> 0.8 | J16: 500 | K16: =52*E16 -> 364 | L16: =F16*G16 -> 46.2 | M16: =F16*D16 -> 28000 | N16: =L16*H16 -> 129360 | O16: =I16*Assumptions!B3*Assumptions!B2 -> 56489.334 | P16: =I16*Assumptions!B7 -> 8000 | Q16: =Data!P16+Assumptions!B4+Assumptions!B5+Assumptions!B6 -> 64000 | R16: =Q16+O16 -> 120489.33 | S16: =N16-R16 -> 8870.666 | T16: =(S16/N16) -> 0.068573485 | U16: Y | V16: =W16/(F16*H16) -> 0.67238368 | W16: =P16+I16*Assumptions!$B$3*Assumptions!$B$2*1.2+Assumptions!$B$4+Assumptions!$B$5+Assumptions!$B$6 -> 131787.2 | X16: =IF(G16>=V16,"Viable","At Risk") -> At Risk | Y16: =IF(V16>Assumptions!$B$12,"Structurally Weak","Potentially Viable") -> Potentially Viable | Z16: =Assumptions!B$10 -> 0.08 | AA16: =H16*(1+Z16) -> 3024 | AB16: =MIN(Assumptions!B$12,G16*(1+Z16*Assumptions!B$11)) -> 0.59136 | AC16: =F16*AB16 -> 41.3952 | AD16: =AC16*(AA16) -> 125179.08 | AE16: =AD16-(P16+I16*Assumptions!$B$3*Assumptions!$B$2*1.2+Assumptions!$B$4+Assumptions!$B$5+Assumptions!$B$6) -> -6608.116 | AF16: =AE16*K16 -> -2405354.2 | AG16: =AE16/AD16 -> -0.052789298 | AH16: ='Scenario Analysis'!D16 -> -2427.2008 | AI16: =IF(AND(AH16<0,U16="N"),"Rationalize","Keep") -> Keep | AJ16: =IF(AI16="Rationalize",0,AH16) -> -2427.2008 | AK16: =AJ16*K16 -> -883501.09 | AL16: =IF(U16="Y",MIN(H16,Assumptions!$B$13*I16),0) -> 2000 | AM16: =IF(U16="Y",L16*Assumptions!$B$14,0) -> 23.1 | AN16: =IF(U16="Y",L16*(1-Assumptions!$B$14),0) -> 23.1 | AO16: =IF(U16="Y",AM16*AL16+AN16*H16+L16*Assumptions!$B$9,0) -> 127050 | AP16: =IF(U16="Y",O16*1.2*(1-Assumptions!$B$15),0) -> 57619.121 | AQ16: =IF(U16="Y",Assumptions!$B$5*(1-Assumptions!$B$16),0) -> 8400 | AR16: =IF(U16="Y",AM16*Assumptions!$B$17,0) -> 34650 | AS16: =IF(U16="Y",AP16+P16+Assumptions!$B$4+AQ16+Assumptions!$B$6,0) -> 116019.12 | AT16: =IF(U16="Y",AO16+AR16-AS16,0) -> 45680.879 | AU16: =AT16*K16 -> 16627840 | AV16: =IFERROR(AT16/(AO16+AR16),0) -> 0.28250389 | AW16: =IF(U16="Y",IF(AT16>=MAX(AH16,AE16,AT16),"UDAN",IF(AE16>=AH16,"Fare Hike","Keep as-is")),IF(AJ16=0,"Rationalize",IF(AE16>=AH16,"Fare Hike","Keep as it is"))) -> UDAN | AX16: =IF(AW16="UDAN",AT16,IF(AW16="Fare Hike",AE16,IF(AW16="Rationalize",0,AH16))) -> 45680.879 | AY16: =AX16*K16 -> 16627840 | AZ16: =AX16-AH16 -> 48108.08
A17: R16 | B17: Diu | C17: Mumbai | D17: 480 | E17: 3 | F17: 70 | G17: 0.58 | H17: 3600 | I17: =D17/J17 -> 0.96 | J17: 500 | K17: =52*E17 -> 156 | L17: =F17*G17 -> 40.6 | M17: =F17*D17 -> 33600 | N17: =L17*H17 -> 146160 | O17: =I17*Assumptions!B3*Assumptions!B2 -> 67787.201 | P17: =I17*Assumptions!B7 -> 9600 | Q17: =Data!P17+Assumptions!B4+Assumptions!B5+Assumptions!B6 -> 65600 | R17: =Q17+O17 -> 133387.2 | S17: =N17-R17 -> 12772.799 | T17: =(S17/N17) -> 0.087389157 | U17: Y | V17: =W17/(F17*H17) -> 0.58311365 | W17: =P17+I17*Assumptions!$B$3*Assumptions!$B$2*1.2+Assumptions!$B$4+Assumptions!$B$5+Assumptions!$B$6 -> 146944.64 | X17: =IF(G17>=V17,"Viable","At Risk") -> At Risk | Y17: =IF(V17>Assumptions!$B$12,"Structurally Weak","Potentially Viable") -> Potentially Viable | Z17: =Assumptions!B$10 -> 0.08 | AA17: =H17*(1+Z17) -> 3888 | AB17: =MIN(Assumptions!B$12,G17*(1+Z17*Assumptions!B$11)) -> 0.51968 | AC17: =F17*AB17 -> 36.3776 | AD17: =AC17*(AA17) -> 141436.11 | AE17: =AD17-(P17+I17*Assumptions!$B$3*Assumptions!$B$2*1.2+Assumptions!$B$4+Assumptions!$B$5+Assumptions!$B$6) -> -5508.5322 | AF17: =AE17*K17 -> -859331.02 | AG17: =AE17/AD17 -> -0.038947142 | AH17: ='Scenario Analysis'!D17 -> -784.64096 | AI17: =IF(AND(AH17<0,U17="N"),"Rationalize","Keep") -> Keep | AJ17: =IF(AI17="Rationalize",0,AH17) -> -784.64096 | AK17: =AJ17*K17 -> -122403.99 | AL17: =IF(U17="Y",MIN(H17,Assumptions!$B$13*I17),0) -> 2400 | AM17: =IF(U17="Y",L17*Assumptions!$B$14,0) -> 20.3 | AN17: =IF(U17="Y",L17*(1-Assumptions!$B$14),0) -> 20.3 | AO17: =IF(U17="Y",AM17*AL17+AN17*H17+L17*Assumptions!$B$9,0) -> 136010 | AP17: =IF(U17="Y",O17*1.2*(1-Assumptions!$B$15),0) -> 69142.945 | AQ17: =IF(U17="Y",Assumptions!$B$5*(1-Assumptions!$B$16),0) -> 8400 | AR17: =IF(U17="Y",AM17*Assumptions!$B$17,0) -> 30450 | AS17: =IF(U17="Y",AP17+P17+Assumptions!$B$4+AQ17+Assumptions!$B$6,0) -> 129142.94 | AT17: =IF(U17="Y",AO17+AR17-AS17,0) -> 37317.055 | AU17: =AT17*K17 -> 5821460.6 | AV17: =IFERROR(AT17/(AO17+AR17),0) -> 0.22418031 | AW17: =IF(U17="Y",IF(AT17>=MAX(AH17,AE17,AT17),"UDAN",IF(AE17>=AH17,"Fare Hike","Keep as-is")),IF(AJ17=0,"Rationalize",IF(AE17>=AH17,"Fare Hike","Keep as it is"))) -> UDAN | AX17: =IF(AW17="UDAN",AT17,IF(AW17="Fare Hike",AE17,IF(AW17="Rationalize",0,AH17))) -> 37317.055 | AY17: =AX17*K17 -> 5821460.6 | AZ17: =AX17-AH17 -> 38101.696
A18: R17 | B18: Kishangarh | C18: Delhi | D18: 350 | E18: 6 | F18: 70 | G18: 0.64 | H18: 2900 | I18: =D18/J18 -> 0.7 | J18: 500 | K18: =52*E18 -> 312 | L18: =F18*G18 -> 44.8 | M18: =F18*D18 -> 24500 | N18: =L18*H18 -> 129920 | O18: =I18*Assumptions!B3*Assumptions!B2 -> 49428.167 | P18: =I18*Assumptions!B7 -> 7000 | Q18: =Data!P18+Assumptions!B4+Assumptions!B5+Assumptions!B6 -> 63000 | R18: =Q18+O18 -> 112428.17 | S18: =N18-R18 -> 17491.833 | T18: =(S18/N18) -> 0.13463541 | U18: Y | V18: =W18/(F18*H18) -> 0.60253104 | W18: =P18+I18*Assumptions!$B$3*Assumptions!$B$2*1.2+Assumptions!$B$4+Assumptions!$B$5+Assumptions!$B$6 -> 122313.8 | X18: =IF(G18>=V18,"Viable","At Risk") -> Viable | Y18: =IF(V18>Assumptions!$B$12,"Structurally Weak","Potentially Viable") -> Potentially Viable | Z18: =Assumptions!B$10 -> 0.08 | AA18: =H18*(1+Z18) -> 3132 | AB18: =MIN(Assumptions!B$12,G18*(1+Z18*Assumptions!B$11)) -> 0.57344 | AC18: =F18*AB18 -> 40.1408 | AD18: =AC18*(AA18) -> 125720.99 | AE18: =AD18-(P18+I18*Assumptions!$B$3*Assumptions!$B$2*1.2+Assumptions!$B$4+Assumptions!$B$5+Assumptions!$B$6) -> 3407.1849 | AF18: =AE18*K18 -> 1063041.7 | AG18: =AE18/AD18 -> 0.027101163 | AH18: ='Scenario Analysis'!D18 -> 7606.1993 | AI18: =IF(AND(AH18<0,U18="N"),"Rationalize","Keep") -> Keep | AJ18: =IF(AI18="Rationalize",0,AH18) -> 7606.1993 | AK18: =AJ18*K18 -> 2373134.2 | AL18: =IF(U18="Y",MIN(H18,Assumptions!$B$13*I18),0) -> 1750 | AM18: =IF(U18="Y",L18*Assumptions!$B$14,0) -> 22.4 | AN18: =IF(U18="Y",L18*(1-Assumptions!$B$14),0) -> 22.4 | AO18: =IF(U18="Y",AM18*AL18+AN18*H18+L18*Assumptions!$B$9,0) -> 119840 | AP18: =IF(U18="Y",O18*1.2*(1-Assumptions!$B$15),0) -> 50416.731 | AQ18: =IF(U18="Y",Assumptions!$B$5*(1-Assumptions!$B$16),0) -> 8400 | AR18: =IF(U18="Y",AM18*Assumptions!$B$17,0) -> 33600 | AS18: =IF(U18="Y",AP18+P18+Assumptions!$B$4+AQ18+Assumptions!$B$6,0) -> 107816.73 | AT18: =IF(U18="Y",AO18+AR18-AS18,0) -> 45623.269 | AU18: =AT18*K18 -> 14234460 | AV18: =IFERROR(AT18/(AO18+AR18),0) -> 0.29733622 | AW18: =IF(U18="Y",IF(AT18>=MAX(AH18,AE18,AT18),"UDAN",IF(AE18>=AH18,"Fare Hike","Keep as-is")),IF(AJ18=0,"Rationalize",IF(AE18>=AH18,"Fare Hike","Keep as it is"))) -> UDAN | AX18: =IF(AW18="UDAN",AT18,IF(AW18="Fare Hike",AE18,IF(AW18="Rationalize",0,AH18))) -> 45623.269 | AY18: =AX18*K18 -> 14234460 | AZ18: =AX18-AH18 -> 38017.07
A19: R18 | B19: Salem | C19: Chennai | D19: 280 | E19: 8 | F19: 70 | G19: 0.77 | H19: 2200 | I19: =D19/J19 -> 0.56 | J19: 500 | K19: =52*E19 -> 416 | L19: =F19*G19 -> 53.9 | M19: =F19*D19 -> 19600 | N19: =L19*H19 -> 118580 | O19: =I19*Assumptions!B3*Assumptions!B2 -> 39542.534 | P19: =I19*Assumptions!B7 -> 5600 | Q19: =Data!P19+Assumptions!B4+Assumptions!B5+Assumptions!B6 -> 61600 | R19: =Q19+O19 -> 101142.53 | S19: =N19-R19 -> 17437.466 | T19: =(S19/N19) -> 0.14705234 | U19: N | V19: =W19/(F19*H19) -> 0.70812364 | W19: =P19+I19*Assumptions!$B$3*Assumptions!$B$2*1.2+Assumptions!$B$4+Assumptions!$B$5+Assumptions!$B$6 -> 109051.04 | X19: =IF(G19>=V19,"Viable","At Risk") -> Viable | Y19: =IF(V19>Assumptions!$B$12,"Structurally Weak","Potentially Viable") -> Potentially Viable | Z19: =Assumptions!B$10 -> 0.08 | AA19: =H19*(1+Z19) -> 2376 | AB19: =MIN(Assumptions!B$12,G19*(1+Z19*Assumptions!B$11)) -> 0.68992 | AC19: =F19*AB19 -> 48.2944 | AD19: =AC19*(AA19) -> 114747.49 | AE19: =AD19-(P19+I19*Assumptions!$B$3*Assumptions!$B$2*1.2+Assumptions!$B$4+Assumptions!$B$5+Assumptions!$B$6) -> 5696.4538 | AF19: =AE19*K19 -> 2369724.8 | AG19: =AE19/AD19 -> 0.049643383 | AH19: ='Scenario Analysis'!D19 -> 9528.9594 | AI19: =IF(AND(AH19<0,U19="N"),"Rationalize","Keep") -> Keep | AJ19: =IF(AI19="Rationalize",0,AH19) -> 9528.9594 | AK19: =AJ19*K19 -> 3964047.1 | AL19: =IF(U19="Y",MIN(H19,Assumptions!$B$13*I19),0) -> 0 | AM19: =IF(U19="Y",L19*Assumptions!$B$14,0) -> 0 | AN19: =IF(U19="Y",L19*(1-Assumptions!$B$14),0) -> 0 | AO19: =IF(U19="Y",AM19*AL19+AN19*H19+L19*Assumptions!$B$9,0) -> 0 | AP19: =IF(U19="Y",O19*1.2*(1-Assumptions!$B$15),0) -> 0 | AQ19: =IF(U19="Y",Assumptions!$B$5*(1-Assumptions!$B$16),0) -> 0 | AR19: =IF(U19="Y",AM19*Assumptions!$B$17,0) -> 0 | AS19: =IF(U19="Y",AP19+P19+Assumptions!$B$4+AQ19+Assumptions!$B$6,0) -> 0 | AT19: =IF(U19="Y",AO19+AR19-AS19,0) -> 0 | AU19: =AT19*K19 -> 0 | AV19: =IFERROR(AT19/(AO19+AR19),0) -> 0 | AW19: =IF(U19="Y",IF(AT19>=MAX(AH19,AE19,AT19),"UDAN",IF(AE19>=AH19,"Fare Hike","Keep as-is")),IF(AJ19=0,"Rationalize",IF(AE19>=AH19,"Fare Hike","Keep as it is"))) -> Keep as it is | AX19: =IF(AW19="UDAN",AT19,IF(AW19="Fare Hike",AE19,IF(AW19="Rationalize",0,AH19))) -> 9528.9594 | AY19: =AX19*K19 -> 3964047.1 | AZ19: =AX19-AH19 -> 0
A20: R19 | B20: Patnagar | C20: Delhi | D20: 220 | E20: 7 | F20: 70 | G20: 0.61 | H20: 2100 | I20: =D20/J20 -> 0.44 | J20: 500 | K20: =52*E20 -> 364 | L20: =F20*G20 -> 42.7 | M20: =F20*D20 -> 15400 | N20: =L20*H20 -> 89670 | O20: =I20*Assumptions!B3*Assumptions!B2 -> 31069.134 | P20: =I20*Assumptions!B7 -> 4400 | Q20: =Data!P20+Assumptions!B4+Assumptions!B5+Assumptions!B6 -> 60400 | R20: =Q20+O20 -> 91469.134 | S20: =N20-R20 -> -1799.1337 | T20: =(S20/N20) -> -0.020063942 | U20: Y | V20: =W20/(F20*H20) -> 0.66450993 | W20: =P20+I20*Assumptions!$B$3*Assumptions!$B$2*1.2+Assumptions!$B$4+Assumptions!$B$5+Assumptions!$B$6 -> 97682.96 | X20: =IF(G20>=V20,"Viable","At Risk") -> At Risk | Y20: =IF(V20>Assumptions!$B$12,"Structurally Weak","Potentially Viable") -> Potentially Viable | Z20: =Assumptions!B$10 -> 0.08 | AA20: =H20*(1+Z20) -> 2268 | AB20: =MIN(Assumptions!B$12,G20*(1+Z20*Assumptions!B$11)) -> 0.54656 | AC20: =F20*AB20 -> 38.2592 | AD20: =AC20*(AA20) -> 86771.866 | AE20: =AD20-(P20+I20*Assumptions!$B$3*Assumptions!$B$2*1.2+Assumptions!$B$4+Assumptions!$B$5+Assumptions!$B$6) -> -10911.095 | AF20: =AE20*K20 -> -3971638.5 | AG20: =AE20/AD20 -> -0.12574462 | AH20: ='Scenario Analysis'!D20 -> -8012.9604 | AI20: =IF(AND(AH20<0,U20="N"),"Rationalize","Keep") -> Keep | AJ20: =IF(AI20="Rationalize",0,AH20) -> -8012.9604 | AK20: =AJ20*K20 -> -2916717.6 | AL20: =IF(U20="Y",MIN(H20,Assumptions!$B$13*I20),0) -> 1100 | AM20: =IF(U20="Y",L20*Assumptions!$B$14,0) -> 21.35 | AN20: =IF(U20="Y",L20*(1-Assumptions!$B$14),0) -> 21.35 | AO20: =IF(U20="Y",AM20*AL20+AN20*H20+L20*Assumptions!$B$9,0) -> 83265 | AP20: =IF(U20="Y",O20*1.2*(1-Assumptions!$B$15),0) -> 31690.516 | AQ20: =IF(U20="Y",Assumptions!$B$5*(1-Assumptions!$B$16),0) -> 8400 | AR20: =IF(U20="Y",AM20*Assumptions!$B$17,0) -> 32025 | AS20: =IF(U20="Y",AP20+P20+Assumptions!$B$4+AQ20+Assumptions!$B$6,0) -> 86490.516 | AT20: =IF(U20="Y",AO20+AR20-AS20,0) -> 28799.484 | AU20: =AT20*K20 -> 10483012 | AV20: =IFERROR(AT20/(AO20+AR20),0) -> 0.24980036 | AW20: =IF(U20="Y",IF(AT20>=MAX(AH20,AE20,AT20),"UDAN",IF(AE20>=AH20,"Fare Hike","Keep as-is")),IF(AJ20=0,"Rationalize",IF(AE20>=AH20,"Fare Hike","Keep as it is"))) -> UDAN | AX20: =IF(AW20="UDAN",AT20,IF(AW20="Fare Hike",AE20,IF(AW20="Rationalize",0,AH20))) -> 28799.484 | AY20: =AX20*K20 -> 10483012 | AZ20: =AX20-AH20 -> 36812.444
A21: R20 | B21: Puducherry | C21: Chennai | D21: 160 | E21: 9 | F21: 70 | G21: 0.79 | H21: 1900 | I21: =D21/J21 -> 0.32 | J21: 500 | K21: =52*E21 -> 468 | L21: =F21*G21 -> 55.3 | M21: =F21*D21 -> 11200 | N21: =L21*H21 -> 105070 | O21: =I21*Assumptions!B3*Assumptions!B2 -> 22595.734 | P21: =I21*Assumptions!B7 -> 3200 | Q21: =Data!P21+Assumptions!B4+Assumptions!B5+Assumptions!B6 -> 59200 | R21: =Q21+O21 -> 81795.734 | S21: =N21-R21 -> 23274.266 | T21: =(S21/N21) -> 0.22151201 | U21: Y | V21: =W21/(F21*H21) -> 0.64898406 | W21: =P21+I21*Assumptions!$B$3*Assumptions!$B$2*1.2+Assumptions!$B$4+Assumptions!$B$5+Assumptions!$B$6 -> 86314.88 | X21: =IF(G21>=V21,"Viable","At Risk") -> Viable | Y21: =IF(V21>Assumptions!$B$12,"Structurally Weak","Potentially Viable") -> Potentially Viable | Z21: =Assumptions!B$10 -> 0.08 | AA21: =H21*(1+Z21) -> 2052 | AB21: =MIN(Assumptions!B$12,G21*(1+Z21*Assumptions!B$11)) -> 0.70784 | AC21: =F21*AB21 -> 49.5488 | AD21: =AC21*(AA21) -> 101674.14 | AE21: =AD21-(P21+I21*Assumptions!$B$3*Assumptions!$B$2*1.2+Assumptions!$B$4+Assumptions!$B$5+Assumptions!$B$6) -> 15359.257 | AF21: =AE21*K21 -> 7188132.4 | AG21: =AE21/AD21 -> 0.15106356 | AH21: ='Scenario Analysis'!D21 -> 18755.12 | AI21: =IF(AND(AH21<0,U21="N"),"Rationalize","Keep") -> Keep | AJ21: =IF(AI21="Rationalize",0,AH21) -> 18755.12 | AK21: =AJ21*K21 -> 8777396 | AL21: =IF(U21="Y",MIN(H21,Assumptions!$B$13*I21),0) -> 800 | AM21: =IF(U21="Y",L21*Assumptions!$B$14,0) -> 27.65 | AN21: =IF(U21="Y",L21*(1-Assumptions!$B$14),0) -> 27.65 | AO21: =IF(U21="Y",AM21*AL21+AN21*H21+L21*Assumptions!$B$9,0) -> 94010 | AP21: =IF(U21="Y",O21*1.2*(1-Assumptions!$B$15),0) -> 23047.648 | AQ21: =IF(U21="Y",Assumptions!$B$5*(1-Assumptions!$B$16),0) -> 8400 | AR21: =IF(U21="Y",AM21*Assumptions!$B$17,0) -> 41475 | AS21: =IF(U21="Y",AP21+P21+Assumptions!$B$4+AQ21+Assumptions!$B$6,0) -> 76647.648 | AT21: =IF(U21="Y",AO21+AR21-AS21,0) -> 58837.352 | AU21: =AT21*K21 -> 27535881 | AV21: =IFERROR(AT21/(AO21+AR21),0) -> 0.43427207 | AW21: =IF(U21="Y",IF(AT21>=MAX(AH21,AE21,AT21),"UDAN",IF(AE21>=AH21,"Fare Hike","Keep as-is")),IF(AJ21=0,"Rationalize",IF(AE21>=AH21,"Fare Hike","Keep as it is"))) -> UDAN | AX21: =IF(AW21="UDAN",AT21,IF(AW21="Fare Hike",AE21,IF(AW21="Rationalize",0,AH21))) -> 58837.352 | AY21: =AX21*K21 -> 27535881 | AZ21: =AX21-AH21 -> 40082.232

Sheet Comparison
A1: Strategy | B1: Annual EBITDA | C1: EBITDA Margin | D1: Improvement vs Do Nothing
A2: Base | B2: =SUMPRODUCT(Data!S2:S21,Data!K2:K21) -> 1.9425068e+08 | C2: =B2/SUMPRODUCT(Data!N2:N21,Data!K2:K21) -> 0.15884738 | D2: =B2-$B$3 -> 97559904
A3: Do Nothing (+20% Fuel) | B3: {=SUM(Data!AH2:AH21*Data!K2:K21)} -> 96690774 | C3: =B3/SUMPRODUCT(Data!N2:N21,Data!K2:K21) -> 0.079068326 | D3: =B3-$B$3 -> 0
A4: Option 1 – Fare Hike | B4: =SUM(Data!AF2:AF21) -> 57167416 | C4: =B4/SUMPRODUCT(Data!AD2:AD21,Data!K2:K21) -> 0.048309696 | D4: =B4-$B$3 -> -39523359
A5: Option 2 – Rationalization | B5: =SUM(Data!AK2:AK21) -> 97796891 | C5: =B5/SUMPRODUCT(Data!N2:N21,Data!K2:K21) -> 0.079972847 | D5: =B5-$B$3 -> 1106116.3
A6: Option 3 – UDAN | B6: =SUM(Data!AU2:AU21) -> 2.8846418e+08 | C6: =B6/(SUMPRODUCT(Data!AO2:AO21,Data!K2:K21)+SUMPRODUCT(Data!AR2:AR21,Data!K2:K21)) -> 0.33796501 | D6: =B6-$B$3 -> 1.9177341e+08
A7: Blended Strategy | B7: =SUM(Data!AY2:AY21) -> 3.2678576e+08 | C7: {=B7/(SUMPRODUCT((Data!AW2:AW21="UDAN")*(Data!AO2:AO21+Data!AR2:AR21)*Data!K2:K21)+SUMPRODUCT((Data!AW2:AW21="Fare Hike")*Data!AD2:AD21*Data!K2:K21)+SUMPRODUCT((Data!AW2:AW21="Keep as is")*Data!N2:N21*Data!K2:K21))} -> 0.38286262 | D7: =B7-$B$3 -> 2.3009499e+08
A9: Key Recommendation | B9: Blended Strategy
A10: Fuel Stress Case | B10: +20% Fuel
A11: Best Network Strategy | B11: Blended Strategy
A12: Network EBITDA | B12: =B7 -> 3.2678576e+08
A13: EBITDA Margin | B13: =C7 -> 0.38286262
A14: Improvement vs Do Nothing | B14: =D7 -> 2.3009499e+08
A17: Route ID | B17: Origin | C17: Destination | D17: Blended Strategy | E17: Blended EBITDA | F17: Improvement vs +20% | H17: Strategy | I17: Number of Routes
A18: =Data!A2 -> R01 | B18: =Data!B2 -> Kanpur | C18: =Data!C2 -> Delhi | D18: =Data!AW2 -> UDAN | E18: =Data!AX2 -> 84898.967 | F18: =Data!AZ2 -> 49544.888 | H18: UDAN | I18: =COUNTIF(Data!AW2:AW21,"UDAN") -> 13
A19: =Data!A3 -> R02 | B19: =Data!B3 -> Jodhpur | C19: =Data!C3 -> Delhi | D19: =Data!AW3 -> Keep as it is | E19: =Data!AX3 -> 18693.879 | F19: =Data!AZ3 -> 0 | H19: Keep as it is | I19: =COUNTIF(Data!AW2:AW21,"Keep as it is") -> 6
A20: =Data!A4 -> R03 | B20: =Data!B4 -> Bhopal | C20: =Data!C4 -> Mumbai | D20: =Data!AW4 -> Rationalize | E20: =Data!AX4 -> 0 | F20: =Data!AZ4 -> 3038.7812 | H20: Rationalize | I20: =COUNTIF(Data!AW2:AW21,"Rationalize") -> 1
A21: =Data!A5 -> R04 | B21: =Data!B5 -> Coimbatore | C21: =Data!C5 -> Chennai | D21: =Data!AW5 -> Keep as it is | E21: =Data!AX5 -> 21909.499 | F21: =Data!AZ5 -> 0 | H21: Fare Hike | I21: =COUNTIF(Data!AW2:AW21,"Fare Hike") -> 0
A22: =Data!A6 -> R05 | B22: =Data!B6 -> Rajkot | C22: =Data!C6 -> Mumbai | D22: =Data!AW6 -> UDAN | E22: =Data!AX6 -> 65385.879 | F22: =Data!AZ6 -> 43103.08
A23: =Data!A7 -> R06 | B23: =Data!B7 -> Varanasi | C23: =Data!C7 -> Delhi | D23: =Data!AW7 -> Keep as it is | E23: =Data!AX7 -> 2491.1187 | F23: =Data!AZ7 -> 0
A24: =Data!A8 -> R07 | B24: =Data!B8 -> Jabalpur | C24: =Data!C8 -> Delhi | D24: =Data!AW8 -> UDAN | E24: =Data!AX8 -> 49596.539 | F24: =Data!AZ8 -> 55944.14
A25: =Data!A9 -> R08 | B25: =Data!B9 -> Aurangabad | C25: =Data!C9 -> Mumbai | D25: =Data!AW9 -> Keep as it is | E25: =Data!AX9 -> 14335.559 | F25: =Data!AZ9 -> 0
A26: =Data!A10 -> R09 | B26: =Data!B10 -> Belgavi | C26: =Data!C10 -> Bengaluru | D26: =Data!AW10 -> UDAN | E26: =Data!AX10 -> 44839.703 | F26: =Data!AZ10 -> 44219.464
A27: =Data!A11 -> R10 | B27: =Data!B11 -> Tirupati | C27: =Data!C11 -> Hyderabad | D27: =Data!AW11 -> Keep as it is | E27: =Data!AX11 -> 3844.7191 | F27: =Data!AZ11 -> 0
A28: =Data!A12 -> R11 | B28: =Data!B12 -> Bikaner | C28: =Data!C12 -> Delhi | D28: =Data!AW12 -> UDAN | E28: =Data!AX12 -> 55132.055 | F28: =Data!AZ12 -> 42826.696
A29: =Data!A13 -> R12 | B29: =Data!B13 -> Jamnagar | C29: =Data!C13 -> Mumbai | D29: =Data!AW13 -> UDAN | E29: =Data!AX13 -> 58877.055 | F29: =Data!AZ13 -> 48741.696
A30: =Data!A14 -> R13 | B30: =Data!B14 -> Kolhapur | C30: =Data!C14 -> Mumbai | D30: =Data!AW14 -> UDAN | E30: =Data!AX14 -> 58621.835 | F30: =Data!AZ14 -> 50539.676
A31: =Data!A15 -> R14 | B31: =Data!B15 -> Gwalior | C31: =Data!C15 -> Delhi | D31: =Data!AW15 -> UDAN | E31: =Data!AX15 -> 60510.659 | F31: =Data!AZ15 -> 47351.06
A32: =Data!A16 -> R15 | B32: =Data!B16 -> Hubali | C32: =Data!C16 -> Bengaluru | D32: =Data!AW16 -> UDAN | E32: =Data!AX16 -> 45680.879 | F32: =Data!AZ16 -> 48108.08
A33: =Data!A17 -> R16 | B33: =Data!B17 -> Diu | C33: =Data!C17 -> Mumbai | D33: =Data!AW17 -> UDAN | E33: =Data!AX17 -> 37317.055 | F33: =Data!AZ17 -> 38101.696
... A37: =Data!A21 -> R20 | B37: =Data!B21 -> Puducherry | C37: =Data!C21 -> Chennai | D37: =Data!AW21 -> UDAN | E37: =Data!AX21 -> 58837.352 | F37: =Data!AZ21 -> 40082.232

Sheet Assumptions
A1: Assumption | B1: Value | C1: Unit
A2: Base ATF Price | B2: 83072.55 | C2: ₹/KL
A3: Fuel Burn | B3: 0.85 | C3: KL/hour
A4: Crew Cost | B4: 22000 | C4: ₹/flight
A5: Airport Cost | B5: 14000 | C5: ₹/flight
A6: Lease Cost | B6: 20000 | C6: ₹/flight
A7: Maintenance Cost | B7: 10000 | C7: ₹/hour
A8: Cruise Speed | B8: 500 | C8: km/hour
A9: Ancillary Revenue / Passenger | B9: 350 | C9: ₹/passenger
A10: Fare Increase | B10: 0.08 | C10: %
A11: Price Elasticity | B11: -1.3 | C11: coefficient
A12: Maximum Realistic Load Factor | B12: 0.82 | C12: %
A13: UDAN Fare Cap | B13: 2500 | C13: ₹/flight-hour
... A17: VGF / RCS Passenger | B17: 1500 | C17: ₹/passenger

Sheet Scenario Analysis
A1: Route ID | B1: Base | C1: +10% Fuel | D1: +20% Fuel | E1: Base CASK | F1: +10% CASK | G1: +20% CASK | H1: Base RASK | I1: +10% RASK | J1: +20% RASK | K1: Base EBITDA margin | L1: +10% EBITDA margin | M1: +20% EBITDA margin | N1: Base Cash Burn | O1: +10% cash burn | P1: +20% cash burn | Q1: Route status (20% fuel)
A2: =Data!A2 -> R01 | B2: =Data!S2 -> 47781.733 | C2: =Data!N2-(Data!P2+Data!I2*Assumptions!$B$3*Assumptions!$B$2*1.1+Assumptions!$B$4+Assumptions!$B$5+Assumptions!$B$6) -> 41567.906 | D2: =Data!N2-(Data!P2+Data!I2*Assumptions!$B$3*Assumptions!$B$2*1.2+Assumptions!$B$4+Assumptions!$B$5+Assumptions!$B$6) -> 35354.079 | E2: =Data!R2/Data!M2 -> 4.1213723 | F2: =(Data!P2+Data!I2*Assumptions!$B$3*Assumptions!$B$2*1.1+Assumptions!$B$4+Assumptions!$B$5+Assumptions!$B$6)/Data!M2 -> 4.3231199 | G2: =(Data!P2+Data!I2*Assumptions!$B$3*Assumptions!$B$2*1.2+Assumptions!$B$4+Assumptions!$B$5+Assumptions!$B$6)/Data!M2 -> 4.5248676 | H2: =Data!N2/Data!M2 -> 5.6727273 | I2: =Data!N2/Data!M2 -> 5.6727273 | J2: =Data!N2/Data!M2 -> 5.6727273 | K2: =(B2/Data!N2)*100 -> 27.347603 | L2: =(C2/Data!N2)*100 -> 23.791155 | M2: =(D2/Data!N2)*100 -> 20.234706 | N2: =MAX(0,-B2*Data!K2/12) -> 0 | O2: =MAX(0,-C2*Data!K2/12) -> 0 | P2: =MAX(0,-D2*Data!K2/12) -> 0 | Q2: =IF(D2<0,"Loss-Making","Profitable") -> Profitable
A3: =Data!A3 -> R02 | B3: =Data!S3 -> 35358.232 | C3: =Data!N3-(Data!P3+Data!I3*Assumptions!$B$3*Assumptions!$B$2*1.1+Assumptions!$B$4+Assumptions!$B$5+Assumptions!$B$6) -> 27026.056 | D3: =Data!N3-(Data!P3+Data!I3*Assumptions!$B$3*Assumptions!$B$2*1.2+Assumptions!$B$4+Assumptions!$B$5+Assumptions!$B$6) -> 18693.879 | E3: =Data!R3/Data!M3 -> 3.6591227 | F3: =(Data!P3+Data!I3*Assumptions!$B$3*Assumptions!$B$2*1.1+Assumptions!$B$4+Assumptions!$B$5+Assumptions!$B$6)/Data!M3 -> 3.8608703 | G3: =(Data!P3+Data!I3*Assumptions!$B$3*Assumptions!$B$2*1.2+Assumptions!$B$4+Assumptions!$B$5+Assumptions!$B$6)/Data!M3 -> 4.0626179 | H3: =Data!N3/Data!M3 -> 4.5152542 | I3: =Data!N3/Data!M3 -> 4.5152542 | J3: =Data!N3/Data!M3 -> 4.5152542 | K3: =(B3/Data!N3)*100 -> 18.960871 | L3: =(C3/Data!N3)*100 -> 14.492737 | M3: =(D3/Data!N3)*100 -> 10.024603 | N3: =MAX(0,-B3*Data!K3/12) -> 0 | O3: =MAX(0,-C3*Data!K3/12) -> 0 | P3: =MAX(0,-D3*Data!K3/12) -> 0 | Q3: =IF(D3<0,"Loss-Making","Profitable") -> Profitable
A4: =Data!A4 -> R03 | B4: =Data!S4 -> 13484.349 | C4: =Data!N4-(Data!P4+Data!I4*Assumptions!$B$3*Assumptions!$B$2*1.1+Assumptions!$B$4+Assumptions!$B$5+Assumptions!$B$6) -> 5222.7839 | D4: =Data!N4-(Data!P4+Data!I4*Assumptions!$B$3*Assumptions!$B$2*1.2+Assumptions!$B$4+Assumptions!$B$5+Assumptions!$B$6) -> -3038.7812 | E4: =Data!R4/Data!M4 -> 3.6707119 | F4: =(Data!P4+Data!I4*Assumptions!$B$3*Assumptions!$B$2*1.1+Assumptions!$B$4+Assumptions!$B$5+Assumptions!$B$6)/Data!M4 -> 3.8724595 | G4: =(Data!P4+Data!I4*Assumptions!$B$3*Assumptions!$B$2*1.2+Assumptions!$B$4+Assumptions!$B$5+Assumptions!$B$6)/Data!M4 -> 4.0742071 | H4: =Data!N4/Data!M4 -> 4 | I4: =Data!N4/Data!M4 -> 4 | J4: =Data!N4/Data!M4 -> 4 | K4: =(B4/Data!N4)*100 -> 8.2322033 | L4: =(C4/Data!N4)*100 -> 3.1885128 | M4: =(D4/Data!N4)*100 -> -1.8551778 | N4: =MAX(0,-B4*Data!K4/12) -> 0 | O4: =MAX(0,-C4*Data!K4/12) -> 0 | P4: =MAX(0,-D4*Data!K4/12) -> 92176.362 | Q4: =IF(D4<0,"Loss-Making","Profitable") -> Loss-Making
A5: =Data!A5 -> R04 | B5: =Data!S5 -> 32501.249 | C5: =Data!N5-(Data!P5+Data!I5*Assumptions!$B$3*Assumptions!$B$2*1.1+Assumptions!$B$4+Assumptions!$B$5+Assumptions!$B$6) -> 27205.374 | D5: =Data!N5-(Data!P5+Data!I5*Assumptions!$B$3*Assumptions!$B$2*1.2+Assumptions!$B$4+Assumptions!$B$5+Assumptions!$B$6) -> 21909.499 | E5: =Data!R5/Data!M5 -> 4.4365238 | F5: =(Data!P5+Data!I5*Assumptions!$B$3*Assumptions!$B$2*1.1+Assumptions!$B$4+Assumptions!$B$5+Assumptions!$B$6)/Data!M5 -> 4.6382715 | G5: =(Data!P5+Data!I5*Assumptions!$B$3*Assumptions!$B$2*1.2+Assumptions!$B$4+Assumptions!$B$5+Assumptions!$B$6)/Data!M5 -> 4.8400191 | H5: =Data!N5/Data!M5 -> 5.6746667 | I5: =Data!N5/Data!M5 -> 5.6746667 | J5: =Data!N5/Data!M5 -> 5.6746667 | K5: =(B5/Data!N5) -> 0.21818776 | L5: =(C5/Data!N5) -> 0.18263543 | M5: =(D5/Data!N5) -> 0.1470831 | N5: =MAX(0,-B5*Data!K5/12) -> 0 | O5: =MAX(0,-C5*Data!K5/12) -> 0 | P5: =MAX(0,-D5*Data!K5/12) -> 0 | Q5: =IF(D5<0,"Loss-Making","Profitable") -> Profitable
A6: =Data!A6 -> R05 | B6: =Data!S6 -> 33580.666 | C6: =Data!N6-(Data!P6+Data!I6*Assumptions!$B$3*Assumptions!$B$2*1.1+Assumptions!$B$4+Assumptions!$B$5+Assumptions!$B$6) -> 27931.733 | D6: =Data!N6-(Data!P6+Data!I6*Assumptions!$B$3*Assumptions!$B$2*1.2+Assumptions!$B$4+Assumptions!$B$5+Assumptions!$B$6) -> 22282.799 | E6: =Data!R6/Data!M6 -> 4.3031905 | F6: =(Data!P6+Data!I6*Assumptions!$B$3*Assumptions!$B$2*1.1+Assumptions!$B$4+Assumptions!$B$5+Assumptions!$B$6)/Data!M6 -> 4.5049381 | G6: =(Data!P6+Data!I6*Assumptions!$B$3*Assumptions!$B$2*1.2+Assumptions!$B$4+Assumptions!$B$5+Assumptions!$B$6)/Data!M6 -> 4.7066857 | H6: =Data!N6/Data!M6 -> 5.5025 | I6: =Data!N6/Data!M6 -> 5.5025 | J6: =Data!N6/Data!M6 -> 5.5025 | K6: =(B6/Data!N6) -> 0.2179572 | L6: =(C6/Data!N6) -> 0.18129248 | M6: =(D6/Data!N6) -> 0.14462776 | N6: =MAX(0,-B6*Data!K6/12) -> 0 | O6: =MAX(0,-C6*Data!K6/12) -> 0 | P6: =MAX(0,-D6*Data!K6/12) -> 0 | Q6: =IF(D6<0,"Loss-Making","Profitable") -> Profitable
A7: =Data!A7 -> R06 | B7: =Data!S7 -> 21132.599 | C7: =Data!N7-(Data!P7+Data!I7*Assumptions!$B$3*Assumptions!$B$2*1.1+Assumptions!$B$4+Assumptions!$B$5+Assumptions!$B$6) -> 11811.859 | D7: =Data!N7-(Data!P7+Data!I7*Assumptions!$B$3*Assumptions!$B$2*1.2+Assumptions!$B$4+Assumptions!$B$5+Assumptions!$B$6) -> 2491.1187 | E7: =Data!R7/Data!M7 -> 3.5153117 | F7: =(Data!P7+Data!I7*Assumptions!$B$3*Assumptions!$B$2*1.1+Assumptions!$B$4+Assumptions!$B$5+Assumptions!$B$6)/Data!M7 -> 3.7170593 | G7: =(Data!P7+Data!I7*Assumptions!$B$3*Assumptions!$B$2*1.2+Assumptions!$B$4+Assumptions!$B$5+Assumptions!$B$6)/Data!M7 -> 3.918807 | H7: =Data!N7/Data!M7 -> 3.9727273 | I7: =Data!N7/Data!M7 -> 3.9727273 | J7: =Data!N7/Data!M7 -> 3.9727273 | K7: =(B7/Data!N7) -> 0.11513893 | L7: =(C7/Data!N7) -> 0.064355774 | M7: =(D7/Data!N7) -> 0.01357262 | N7: =MAX(0,-B7*Data!K7/12) -> 0 | O7: =MAX(0,-C7*Data!K7/12) -> 0 | P7: =MAX(0,-D7*Data!K7/12) -> 0 | Q7: =IF(D7<0,"Loss-Making","Profitable") -> Profitable
A8: =Data!A8 -> R07 | B8: =Data!S8 -> 13423.666 | C8: =Data!N8-(Data!P8+Data!I8*Assumptions!$B$3*Assumptions!$B$2*1.1+Assumptions!$B$4+Assumptions!$B$5+Assumptions!$B$6) -> 3538.032 | D8: =Data!N8-(Data!P8+Data!I8*Assumptions!$B$3*Assumptions!$B$2*1.2+Assumptions!$B$4+Assumptions!$B$5+Assumptions!$B$6) -> -6347.6014 | E8: =Data!R8/Data!M8 -> 3.4460476 | F8: =(Data!P8+Data!I8*Assumptions!$B$3*Assumptions!$B$2*1.1+Assumptions!$B$4+Assumptions!$B$5+Assumptions!$B$6)/Data!M8 -> 3.6477953 | G8: =(Data!P8+Data!I8*Assumptions!$B$3*Assumptions!$B$2*1.2+Assumptions!$B$4+Assumptions!$B$5+Assumptions!$B$6)/Data!M8 -> 3.8495429 | H8: =Data!N8/Data!M8 -> 3.72 | I8: =Data!N8/Data!M8 -> 3.72 | J8: =Data!N8/Data!M8 -> 3.72 | K8: =(B8/Data!N8) -> 0.073643107 | L8: =(C8/Data!N8) -> 0.019409875 | M8: =(D8/Data!N8) -> -0.034823356 | N8: =MAX(0,-B8*Data!K8/12) -> 0 | O8: =MAX(0,-C8*Data!K8/12) -> 0 | P8: =MAX(0,-D8*Data!K8/12) -> 137531.36 | Q8: =IF(D8<0,"Loss-Making","Profitable") -> Loss-Making
